Traceback (most recent call last):
  File "/home/pbellec/env/psy3018/lib/python3.8/site-packages/jupyter_cache/executors/utils.py", line 51, in single_nb_execution
    executenb(
  File "/home/pbellec/env/psy3018/lib/python3.8/site-packages/nbclient/client.py", line 1112, in execute
    return NotebookClient(nb=nb, resources=resources, km=km, **kwargs).execute()
  File "/home/pbellec/env/psy3018/lib/python3.8/site-packages/nbclient/util.py", line 74, in wrapped
    return just_run(coro(*args, **kwargs))
  File "/home/pbellec/env/psy3018/lib/python3.8/site-packages/nbclient/util.py", line 53, in just_run
    return loop.run_until_complete(coro)
  File "/usr/lib/python3.8/asyncio/base_events.py", line 616, in run_until_complete
    return future.result()
  File "/home/pbellec/env/psy3018/lib/python3.8/site-packages/nbclient/client.py", line 553, in async_execute
    await self.async_execute_cell(
  File "/home/pbellec/env/psy3018/lib/python3.8/site-packages/nbclient/client.py", line 857, in async_execute_cell
    self._check_raise_for_error(cell, exec_reply)
  File "/home/pbellec/env/psy3018/lib/python3.8/site-packages/nbclient/client.py", line 760, in _check_raise_for_error
    raise CellExecutionError.from_cell_and_msg(cell, exec_reply_content)
nbclient.exceptions.CellExecutionError: An error occurred while executing the following cell:
------------------
from nilearn.plotting import plot_design_matrix
fig, ax = plt.subplots(ncols=5, figsize=(6, 12), sharey=True)
Y = df["MG1"].to_numpy()
X = design_matrix.to_numpy()
ax[0].plot(np.expand_dims(Y, axis=1), range(len(Y)))
ax[1].plot(X[:,0], range(len(Y)))
ax[2].plot(X[:,1], range(len(Y)))
ax[3].plot(X[:,2], range(len(Y)))
ax[0].set_ylabel('# sujet', fontsize=18)
ax[0].set_title('MG', fontsize=20)
ax[1].set_title('Ã‚ge', fontsize=20)
ax[2].set_title('Sexe', fontsize=20)
ax[3].set_title('Intercept', fontsize=20)
plot_design_matrix(design_matrix, ax=ax[4])
ax[4].set_title('Matrice de dessein', fontsize=12)
ax[4].set_ylabel('# sujet')
plt.gca().invert_yaxis()
plt.tight_layout()

# On colle la figure dans le jupyter book
from myst_nb import glue
glue("design-matrix-fig", fig, display=False)           
------------------

[0;31m--------------------------------------------------------------------[0m
[0;31mIndexError[0m                         Traceback (most recent call last)
[0;32m<ipython-input-5-a86d5894c003>[0m in [0;36m<module>[0;34m[0m
[1;32m      6[0m [0max[0m[0;34m[[0m[0;36m1[0m[0;34m][0m[0;34m.[0m[0mplot[0m[0;34m([0m[0mX[0m[0;34m[[0m[0;34m:[0m[0;34m,[0m[0;36m0[0m[0;34m][0m[0;34m,[0m [0mrange[0m[0;34m([0m[0mlen[0m[0;34m([0m[0mY[0m[0;34m)[0m[0;34m)[0m[0;34m)[0m[0;34m[0m[0;34m[0m[0m
[1;32m      7[0m [0max[0m[0;34m[[0m[0;36m2[0m[0;34m][0m[0;34m.[0m[0mplot[0m[0;34m([0m[0mX[0m[0;34m[[0m[0;34m:[0m[0;34m,[0m[0;36m1[0m[0;34m][0m[0;34m,[0m [0mrange[0m[0;34m([0m[0mlen[0m[0;34m([0m[0mY[0m[0;34m)[0m[0;34m)[0m[0;34m)[0m[0;34m[0m[0;34m[0m[0m
[0;32m----> 8[0;31m [0max[0m[0;34m[[0m[0;36m3[0m[0;34m][0m[0;34m.[0m[0mplot[0m[0;34m([0m[0mX[0m[0;34m[[0m[0;34m:[0m[0;34m,[0m[0;36m2[0m[0;34m][0m[0;34m,[0m [0mrange[0m[0;34m([0m[0mlen[0m[0;34m([0m[0mY[0m[0;34m)[0m[0;34m)[0m[0;34m)[0m[0;34m[0m[0;34m[0m[0m
[0m[1;32m      9[0m [0max[0m[0;34m[[0m[0;36m0[0m[0;34m][0m[0;34m.[0m[0mset_ylabel[0m[0;34m([0m[0;34m'# sujet'[0m[0;34m,[0m [0mfontsize[0m[0;34m=[0m[0;36m18[0m[0;34m)[0m[0;34m[0m[0;34m[0m[0m
[1;32m     10[0m [0max[0m[0;34m[[0m[0;36m0[0m[0;34m][0m[0;34m.[0m[0mset_title[0m[0;34m([0m[0;34m'MG'[0m[0;34m,[0m [0mfontsize[0m[0;34m=[0m[0;36m20[0m[0;34m)[0m[0;34m[0m[0;34m[0m[0m

[0;31mIndexError[0m: index 2 is out of bounds for axis 1 with size 2
IndexError: index 2 is out of bounds for axis 1 with size 2

