Traceback (most recent call last):
  File "/home/pbellec/env/psy3018/lib/python3.8/site-packages/jupyter_cache/executors/utils.py", line 51, in single_nb_execution
    executenb(
  File "/home/pbellec/env/psy3018/lib/python3.8/site-packages/nbclient/client.py", line 1112, in execute
    return NotebookClient(nb=nb, resources=resources, km=km, **kwargs).execute()
  File "/home/pbellec/env/psy3018/lib/python3.8/site-packages/nbclient/util.py", line 74, in wrapped
    return just_run(coro(*args, **kwargs))
  File "/home/pbellec/env/psy3018/lib/python3.8/site-packages/nbclient/util.py", line 53, in just_run
    return loop.run_until_complete(coro)
  File "/usr/lib/python3.8/asyncio/base_events.py", line 616, in run_until_complete
    return future.result()
  File "/home/pbellec/env/psy3018/lib/python3.8/site-packages/nbclient/client.py", line 553, in async_execute
    await self.async_execute_cell(
  File "/home/pbellec/env/psy3018/lib/python3.8/site-packages/nbclient/client.py", line 857, in async_execute_cell
    self._check_raise_for_error(cell, exec_reply)
  File "/home/pbellec/env/psy3018/lib/python3.8/site-packages/nbclient/client.py", line 760, in _check_raise_for_error
    raise CellExecutionError.from_cell_and_msg(cell, exec_reply_content)
nbclient.exceptions.CellExecutionError: An error occurred while executing the following cell:
------------------
# Ce code r√©cup√®re des donn√©es IRM T1
# et g√©n√®re une image dans trois plans de coupes

# Enl√®ve les warnings
import warnings
warnings.filterwarnings("ignore")

# T√©l√©charge un scan anatomique (template MNI152)
from nilearn.datasets import fetch_icbm152_2009
mni = fetch_icbm152_2009()

# Visualise le volume c√©r√©bral
from nilearn.plotting import view_img

view_img(
    mni.t1,
    bg_img=None,
    black_bg=True,
    axes=fig.gca(),
    cut_coords=[-17, 0, 17],
    title='IRM pond√©r√©e en T1',
    cmap = 'gray',
    symmetric_cmap=False
)
------------------

[0;31m---------------------------------------------------------------------------[0m
[0;31mAttributeError[0m                            Traceback (most recent call last)
[0;32m<ipython-input-6-99e45ab966a6>[0m in [0;36m<module>[0;34m[0m
[1;32m     17[0m     [0mbg_img[0m[0;34m=[0m[0;32mNone[0m[0;34m,[0m[0;34m[0m[0;34m[0m[0m
[1;32m     18[0m     [0mblack_bg[0m[0;34m=[0m[0;32mTrue[0m[0;34m,[0m[0;34m[0m[0;34m[0m[0m
[0;32m---> 19[0;31m     [0maxes[0m[0;34m=[0m[0mfig[0m[0;34m.[0m[0mgca[0m[0;34m([0m[0;34m)[0m[0;34m,[0m[0;34m[0m[0;34m[0m[0m
[0m[1;32m     20[0m     [0mcut_coords[0m[0;34m=[0m[0;34m[[0m[0;34m-[0m[0;36m17[0m[0;34m,[0m [0;36m0[0m[0;34m,[0m [0;36m17[0m[0;34m][0m[0;34m,[0m[0;34m[0m[0;34m[0m[0m
[1;32m     21[0m     [0mtitle[0m[0;34m=[0m[0;34m'IRM pond√©r√©e en T1'[0m[0;34m,[0m[0;34m[0m[0;34m[0m[0m

[0;31mAttributeError[0m: 'OrthoSlicer' object has no attribute 'gca'
AttributeError: 'OrthoSlicer' object has no attribute 'gca'

