Traceback (most recent call last):
  File "/home/pbellec/env/psy3018/lib/python3.8/site-packages/jupyter_cache/executors/utils.py", line 51, in single_nb_execution
    executenb(
  File "/home/pbellec/env/psy3018/lib/python3.8/site-packages/nbclient/client.py", line 1112, in execute
    return NotebookClient(nb=nb, resources=resources, km=km, **kwargs).execute()
  File "/home/pbellec/env/psy3018/lib/python3.8/site-packages/nbclient/util.py", line 74, in wrapped
    return just_run(coro(*args, **kwargs))
  File "/home/pbellec/env/psy3018/lib/python3.8/site-packages/nbclient/util.py", line 53, in just_run
    return loop.run_until_complete(coro)
  File "/usr/lib/python3.8/asyncio/base_events.py", line 616, in run_until_complete
    return future.result()
  File "/home/pbellec/env/psy3018/lib/python3.8/site-packages/nbclient/client.py", line 553, in async_execute
    await self.async_execute_cell(
  File "/home/pbellec/env/psy3018/lib/python3.8/site-packages/nbclient/client.py", line 857, in async_execute_cell
    self._check_raise_for_error(cell, exec_reply)
  File "/home/pbellec/env/psy3018/lib/python3.8/site-packages/nbclient/client.py", line 760, in _check_raise_for_error
    raise CellExecutionError.from_cell_and_msg(cell, exec_reply_content)
nbclient.exceptions.CellExecutionError: An error occurred while executing the following cell:
------------------
# T√©l√©chargement de l'atlas Harvard-Oxford
from nilearn import datasets

# Enl√®ve les warnings
import warnings
warnings.filterwarnings("ignore")

dataset = datasets.fetch_atlas_harvard_oxford('cort-maxprob-thr25-2mm')
atlas_filename = dataset.maps

# Visualisation de la figure
from myst_nb import glue
from nilearn import plotting

fig = plt.figure(figsize=(12, 4))
plotting.plot_roi(atlas_filename,
    axes=fig.gca(),
    title="Harvard Oxford atlas",
    cut_coords=(8, -4, 9),
    colorbar=True,
    cmap='Paired')

glue("harvard-oxford-fig", fig, display=False)
------------------

[0;31m---------------------------------------------------------------------------[0m
[0;31mNameError[0m                                 Traceback (most recent call last)
[0;32m<ipython-input-1-033b58b5783b>[0m in [0;36m<module>[0;34m[0m
[1;32m     13[0m [0;32mfrom[0m [0mnilearn[0m [0;32mimport[0m [0mplotting[0m[0;34m[0m[0;34m[0m[0m
[1;32m     14[0m [0;34m[0m[0m
[0;32m---> 15[0;31m [0mfig[0m [0;34m=[0m [0mplt[0m[0;34m.[0m[0mfigure[0m[0;34m([0m[0mfigsize[0m[0;34m=[0m[0;34m([0m[0;36m12[0m[0;34m,[0m [0;36m4[0m[0;34m)[0m[0;34m)[0m[0;34m[0m[0;34m[0m[0m
[0m[1;32m     16[0m plotting.plot_roi(atlas_filename,
[1;32m     17[0m     [0maxes[0m[0;34m=[0m[0mfig[0m[0;34m.[0m[0mgca[0m[0;34m([0m[0;34m)[0m[0;34m,[0m[0;34m[0m[0;34m[0m[0m

[0;31mNameError[0m: name 'plt' is not defined
NameError: name 'plt' is not defined

