Traceback (most recent call last):
  File "/home/pbellec/env/psy3018/lib/python3.8/site-packages/jupyter_cache/executors/utils.py", line 51, in single_nb_execution
    executenb(
  File "/home/pbellec/env/psy3018/lib/python3.8/site-packages/nbclient/client.py", line 1112, in execute
    return NotebookClient(nb=nb, resources=resources, km=km, **kwargs).execute()
  File "/home/pbellec/env/psy3018/lib/python3.8/site-packages/nbclient/util.py", line 74, in wrapped
    return just_run(coro(*args, **kwargs))
  File "/home/pbellec/env/psy3018/lib/python3.8/site-packages/nbclient/util.py", line 53, in just_run
    return loop.run_until_complete(coro)
  File "/usr/lib/python3.8/asyncio/base_events.py", line 616, in run_until_complete
    return future.result()
  File "/home/pbellec/env/psy3018/lib/python3.8/site-packages/nbclient/client.py", line 553, in async_execute
    await self.async_execute_cell(
  File "/home/pbellec/env/psy3018/lib/python3.8/site-packages/nbclient/client.py", line 857, in async_execute_cell
    self._check_raise_for_error(cell, exec_reply)
  File "/home/pbellec/env/psy3018/lib/python3.8/site-packages/nbclient/client.py", line 760, in _check_raise_for_error
    raise CellExecutionError.from_cell_and_msg(cell, exec_reply_content)
nbclient.exceptions.CellExecutionError: An error occurred while executing the following cell:
------------------
# Importe les librairies
import numpy as np
import matplotlib.pyplot as plt
from skimage.data import shepp_logan_phantom
from skimage.transform import radon, rescale

# T√©l√©charge donn√©es fant√¥me
image = shepp_logan_phantom()
image = rescale(image, scale=0.4, mode='reflect', channel_axis=None)

# Pr√©pare la figure
fig, (ax1, ax2, ax3) = plt.subplots(1, 3, figsize=(12, 4.5))

# Image originale
ax1.set_title("Original")
ax1.imshow(image, cmap=plt.cm.Greys_r)

# Projections
theta = np.linspace(0., 180., max(image.shape), endpoint=False)
sinogram = radon(image, theta=theta)
dx, dy = 0.5 * 180.0 / max(image.shape), 0.5 / sinogram.shape[0]
ax2.set_title("projections")
ax2.set_xlabel("Angle projection (deg)")
ax2.set_ylabel("Position projection(pixels)")
ax2.imshow(sinogram, cmap=plt.cm.Greys_r,
           extent=(-dx, 180.0 + dx, -dy, sinogram.shape[0] + dy),
           aspect='auto')

# Reconstruction
from skimage.transform import iradon

reconstruction_fbp = iradon(sinogram, theta=theta, filter_name='ramp')
imkwargs = dict(vmin=-0.2, vmax=0.2)
ax3.set_title("Reconstruction")
ax3.imshow(reconstruction_fbp, cmap=plt.cm.Greys_r)
fig.tight_layout()

from myst_nb import glue
glue("projection-fig", fig, display=False)
------------------

[0;31m---------------------------------------------------------------------------[0m
[0;31mTypeError[0m                                 Traceback (most recent call last)
[0;32m<ipython-input-2-782d19e90e91>[0m in [0;36m<module>[0;34m[0m
[1;32m      7[0m [0;31m# T√©l√©charge donn√©es fant√¥me[0m[0;34m[0m[0;34m[0m[0;34m[0m[0m
[1;32m      8[0m [0mimage[0m [0;34m=[0m [0mshepp_logan_phantom[0m[0;34m([0m[0;34m)[0m[0;34m[0m[0;34m[0m[0m
[0;32m----> 9[0;31m [0mimage[0m [0;34m=[0m [0mrescale[0m[0;34m([0m[0mimage[0m[0;34m,[0m [0mscale[0m[0;34m=[0m[0;36m0.4[0m[0;34m,[0m [0mmode[0m[0;34m=[0m[0;34m'reflect'[0m[0;34m,[0m [0mchannel_axis[0m[0;34m=[0m[0;32mNone[0m[0;34m)[0m[0;34m[0m[0;34m[0m[0m
[0m[1;32m     10[0m [0;34m[0m[0m
[1;32m     11[0m [0;31m# Pr√©pare la figure[0m[0;34m[0m[0;34m[0m[0;34m[0m[0m

[0;31mTypeError[0m: rescale() got an unexpected keyword argument 'channel_axis'
TypeError: rescale() got an unexpected keyword argument 'channel_axis'

